Running via Spring preloader in process 5488
Traceback (most recent call last):
  File "/home/aman/anaconda3/lib/python3.7/site-packages/urllib3/connection.py", line 157, in _new_conn
    (self._dns_host, self.port), self.timeout, **extra_kw
  File "/home/aman/anaconda3/lib/python3.7/site-packages/urllib3/util/connection.py", line 61, in create_connection
    for res in socket.getaddrinfo(host, port, family, socket.SOCK_STREAM):
  File "/home/aman/anaconda3/lib/python3.7/socket.py", line 752, in getaddrinfo
    for res in _socket.getaddrinfo(host, port, family, type, proto, flags):
socket.gaierror: [Errno -2] Name or service not known

During handling of the above exception, another exception occurred:

Traceback (most recent call last):
  File "/home/aman/anaconda3/lib/python3.7/site-packages/urllib3/connectionpool.py", line 672, in urlopen
    chunked=chunked,
  File "/home/aman/anaconda3/lib/python3.7/site-packages/urllib3/connectionpool.py", line 376, in _make_request
    self._validate_conn(conn)
  File "/home/aman/anaconda3/lib/python3.7/site-packages/urllib3/connectionpool.py", line 994, in _validate_conn
    conn.connect()
  File "/home/aman/anaconda3/lib/python3.7/site-packages/urllib3/connection.py", line 300, in connect
    conn = self._new_conn()
  File "/home/aman/anaconda3/lib/python3.7/site-packages/urllib3/connection.py", line 169, in _new_conn
    self, "Failed to establish a new connection: %s" % e
urllib3.exceptions.NewConnectionError: <urllib3.connection.VerifiedHTTPSConnection object at 0x7fda973ee950>: Failed to establish a new connection: [Errno -2] Name or service not known

During handling of the above exception, another exception occurred:

Traceback (most recent call last):
  File "/home/aman/anaconda3/lib/python3.7/site-packages/requests/adapters.py", line 449, in send
    timeout=timeout
  File "/home/aman/anaconda3/lib/python3.7/site-packages/urllib3/connectionpool.py", line 720, in urlopen
    method, url, error=e, _pool=self, _stacktrace=sys.exc_info()[2]
  File "/home/aman/anaconda3/lib/python3.7/site-packages/urllib3/util/retry.py", line 436, in increment
    raise MaxRetryError(_pool, url, error or ResponseError(cause))
urllib3.exceptions.MaxRetryError: HTTPSConnectionPool(host='stream.twitter.com', port=443): Max retries exceeded with url: /1.1/statuses/filter.json?delimited=length (Caused by NewConnectionError('<urllib3.connection.VerifiedHTTPSConnection object at 0x7fda973ee950>: Failed to establish a new connection: [Errno -2] Name or service not known'))

During handling of the above exception, another exception occurred:

Traceback (most recent call last):
  File "new_crimes.py", line 96, in <module>
    streamer.filter(track=WORDS)
  File "/home/aman/anaconda3/lib/python3.7/site-packages/tweepy/streaming.py", line 474, in filter
    self._start(is_async)
  File "/home/aman/anaconda3/lib/python3.7/site-packages/tweepy/streaming.py", line 389, in _start
    self._run()
  File "/home/aman/anaconda3/lib/python3.7/site-packages/tweepy/streaming.py", line 320, in _run
    six.reraise(*exc_info)
  File "/home/aman/anaconda3/lib/python3.7/site-packages/six.py", line 703, in reraise
    raise value
  File "/home/aman/anaconda3/lib/python3.7/site-packages/tweepy/streaming.py", line 273, in _run
    proxies = self.proxies)
  File "/home/aman/anaconda3/lib/python3.7/site-packages/requests/sessions.py", line 530, in request
    resp = self.send(prep, **send_kwargs)
  File "/home/aman/anaconda3/lib/python3.7/site-packages/requests/sessions.py", line 643, in send
    r = adapter.send(request, **kwargs)
  File "/home/aman/anaconda3/lib/python3.7/site-packages/requests/adapters.py", line 516, in send
    raise ConnectionError(e, request=request)
requests.exceptions.ConnectionError: HTTPSConnectionPool(host='stream.twitter.com', port=443): Max retries exceeded with url: /1.1/statuses/filter.json?delimited=length (Caused by NewConnectionError('<urllib3.connection.VerifiedHTTPSConnection object at 0x7fda973ee950>: Failed to establish a new connection: [Errno -2] Name or service not known'))
Running via Spring preloader in process 11877
